<sdf version='1.6'>
  <world name='default'>
    <light name='sun' type='directional'>
      <cast_shadows>1</cast_shadows>
      <pose frame=''>0 0 10 0 -0 0</pose>
      <diffuse>0.8 0.8 0.8 1</diffuse>
      <specular>0.2 0.2 0.2 1</specular>
      <attenuation>
        <range>1000</range>
        <constant>0.9</constant>
        <linear>0.01</linear>
        <quadratic>0.001</quadratic>
      </attenuation>
      <direction>-0.5 0.1 -0.9</direction>
    </light>
    <model name='ground_plane'>
      <static>1</static>
      <link name='link'>
        <collision name='collision'>
          <geometry>
            <plane>
              <normal>0 0 1</normal>
              <size>100 100</size>
            </plane>
          </geometry>
          <surface>
            <friction>
              <ode>
                <mu>100</mu>
                <mu2>50</mu2>
              </ode>
              <torsional>
                <ode/>
              </torsional>
            </friction>
            <contact>
              <ode/>
            </contact>
            <bounce/>
          </surface>
          <max_contacts>10</max_contacts>
        </collision>
        <visual name='visual'>
          <cast_shadows>0</cast_shadows>
          <geometry>
            <plane>
              <normal>0 0 1</normal>
              <size>100 100</size>
            </plane>
          </geometry>
          <material>
            <script>
              <uri>file://media/materials/scripts/gazebo.material</uri>
              <name>Gazebo/Grey</name>
            </script>
          </material>
        </visual>
        <self_collide>0</self_collide>
        <kinematic>0</kinematic>
      </link>
    </model>
    
    <gravity>0 0 -9.8</gravity>
    <magnetic_field>6e-06 2.3e-05 -4.2e-05</magnetic_field>
    <atmosphere type='adiabatic'/>
    <physics name='default_physics' default='0' type='ode'>
      <max_step_size>0.001</max_step_size>
      <real_time_factor>1</real_time_factor>
      <real_time_update_rate>1000</real_time_update_rate>
    </physics>
    <scene>
      <ambient>0.4 0.4 0.4 1</ambient>
      <background>0.7 0.7 0.7 1</background>
      <shadows>1</shadows>
    </scene>
    <spherical_coordinates>
      <surface_model>EARTH_WGS84</surface_model>
      <latitude_deg>0</latitude_deg>
      <longitude_deg>0</longitude_deg>
      <elevation>0</elevation>
      <heading_deg>0</heading_deg>
    </spherical_coordinates>
    
    <model name='pioneer2dx'>
      <link name='chassis'>
        <pose frame=''>0 0 0.16 0 -0 0</pose>
        <inertial>
          <mass>5.67</mass>
          <inertia>
            <ixx>0.07</ixx>
            <iyy>0.08</iyy>
            <izz>0.1</izz>
            <ixy>0</ixy>
            <ixz>0</ixz>
            <iyz>0</iyz>
          </inertia>
        </inertial>
        <collision name='collision'>
          <geometry>
            <box>
              <size>0.445 0.277 0.17</size>
            </box>
          </geometry>
          <max_contacts>10</max_contacts>
          <surface>
            <contact>
              <ode/>
            </contact>
            <bounce/>
            <friction>
              <torsional>
                <ode/>
              </torsional>
              <ode/>
            </friction>
          </surface>
        </collision>
        <collision name='castor_collision'>
          <pose frame=''>-0.2 0 -0.12 0 -0 0</pose>
          <geometry>
            <sphere>
              <radius>0.04</radius>
            </sphere>
          </geometry>
          <surface>
            <friction>
              <ode>
                <mu>0</mu>
                <mu2>0</mu2>
                <slip1>1</slip1>
                <slip2>1</slip2>
              </ode>
              <torsional>
                <ode/>
              </torsional>
            </friction>
            <contact>
              <ode/>
            </contact>
            <bounce/>
          </surface>
          <max_contacts>10</max_contacts>
        </collision>
        <visual name='visual'>
          <pose frame=''>0 0 0.04 0 -0 0</pose>
          <geometry>
            <mesh>
              <uri>model://pioneer2dx/meshes/chassis.dae</uri>
            </mesh>
          </geometry>
        </visual>
        <visual name='castor_visual'>
          <pose frame=''>-0.2 0 -0.12 0 -0 0</pose>
          <geometry>
            <sphere>
              <radius>0.04</radius>
            </sphere>
          </geometry>
          <material>
            <script>
              <uri>file://media/materials/scripts/gazebo.material</uri>
              <name>Gazebo/FlatBlack</name>
            </script>
          </material>
        </visual>
        <self_collide>0</self_collide>
        <kinematic>0</kinematic>
      </link>
      <link name='right_wheel'>
        <pose frame=''>0.1 -0.17 0.11 -0 1.5707 1.5707</pose>
        <inertial>
          <mass>1.5</mass>
          <inertia>
            <ixx>0.0051</ixx>
            <iyy>0.0051</iyy>
            <izz>0.009</izz>
            <ixy>0</ixy>
            <ixz>0</ixz>
            <iyz>0</iyz>
          </inertia>
        </inertial>
        <collision name='collision'>
          <geometry>
            <cylinder>
              <radius>0.11</radius>
              <length>0.05</length>
            </cylinder>
          </geometry>
          <surface>
            <friction>
              <ode>
                <mu>100000</mu>
                <mu2>100000</mu2>
                <slip1>0</slip1>
                <slip2>0</slip2>
              </ode>
              <torsional>
                <ode/>
              </torsional>
            </friction>
            <contact>
              <ode/>
            </contact>
            <bounce/>
          </surface>
          <max_contacts>10</max_contacts>
        </collision>
        <visual name='visual'>
          <geometry>
            <cylinder>
              <radius>0.11</radius>
              <length>0.05</length>
            </cylinder>
          </geometry>
          <material>
            <script>
              <uri>file://media/materials/scripts/gazebo.material</uri>
              <name>Gazebo/FlatBlack</name>
            </script>
          </material>
        </visual>
        <self_collide>0</self_collide>
        <kinematic>0</kinematic>
      </link>
      <link name='left_wheel'>
        <pose frame=''>0.1 0.17 0.11 -0 1.5707 1.5707</pose>
        <inertial>
          <mass>1.5</mass>
          <inertia>
            <ixx>0.0051</ixx>
            <iyy>0.0051</iyy>
            <izz>0.009</izz>
            <ixy>0</ixy>
            <ixz>0</ixz>
            <iyz>0</iyz>
          </inertia>
        </inertial>
        <collision name='collision'>
          <geometry>
            <cylinder>
              <radius>0.11</radius>
              <length>0.05</length>
            </cylinder>
          </geometry>
          <surface>
            <friction>
              <ode>
                <mu>100000</mu>
                <mu2>100000</mu2>
                <slip1>0</slip1>
                <slip2>0</slip2>
              </ode>
              <torsional>
                <ode/>
              </torsional>
            </friction>
            <contact>
              <ode/>
            </contact>
            <bounce/>
          </surface>
          <max_contacts>10</max_contacts>
        </collision>
        <visual name='visual'>
          <geometry>
            <cylinder>
              <radius>0.11</radius>
              <length>0.05</length>
            </cylinder>
          </geometry>
          <material>
            <script>
              <uri>file://media/materials/scripts/gazebo.material</uri>
              <name>Gazebo/FlatBlack</name>
            </script>
          </material>
        </visual>
        <self_collide>0</self_collide>
        <kinematic>0</kinematic>
      </link>
      <joint name='left_wheel_hinge' type='revolute'>
        <pose frame=''>0 0 -0.03 0 -0 0</pose>
        <child>left_wheel</child>
        <parent>chassis</parent>
        <axis>
          <xyz>0 1 0</xyz>
          <use_parent_model_frame>1</use_parent_model_frame>
          <limit>
            <lower>-1e+16</lower>
            <upper>1e+16</upper>
          </limit>
          <dynamics>
            <spring_reference>0</spring_reference>
            <spring_stiffness>0</spring_stiffness>
          </dynamics>
        </axis>
      </joint>
      <joint name='right_wheel_hinge' type='revolute'>
        <pose frame=''>0 0 0.03 0 -0 0</pose>
        <child>right_wheel</child>
        <parent>chassis</parent>
        <axis>
          <xyz>0 1 0</xyz>
          <use_parent_model_frame>1</use_parent_model_frame>
          <limit>
            <lower>-1e+16</lower>
            <upper>1e+16</upper>
          </limit>
          <dynamics>
            <spring_reference>0</spring_reference>
            <spring_stiffness>0</spring_stiffness>
          </dynamics>
        </axis>
      </joint>
      <plugin name='diff_drive' filename='libDiffDrivePlugin.so'>
        <left_joint>left_wheel_hinge</left_joint>
        <right_joint>right_wheel_hinge</right_joint>
        <torque>5</torque>
      </plugin>
      <pose frame=''>0.086216 -0.023048 0 0 -0 0</pose>
    </model>
    
    <state world_name='default'>
      <sim_time>121 33000000</sim_time>
      <real_time>121 313728502</real_time>
      <wall_time>1542479191 449683670</wall_time>
      <iterations>121033</iterations>
      <model name='ground_plane'>
        <pose frame=''>0 0 0 0 -0 0</pose>
        <scale>1 1 1</scale>
        <link name='link'>
          <pose frame=''>0 0 0 0 -0 0</pose>
          <velocity>0 0 0 0 -0 0</velocity>
          <acceleration>0 0 0 0 -0 0</acceleration>
          <wrench>0 0 0 0 -0 0</wrench>
        </link>
      </model>
      
      <model name='pioneer2dx'>
        <pose frame=''>0.224878 -0.018178 -3e-06 3e-05 1.5e-05 0.19694</pose>
        <scale>1 1 1</scale>
        <link name='chassis'>
          <pose frame=''>0.224881 -0.018182 0.159997 3e-05 1.5e-05 0.19694</pose>
          <velocity>0.003495 0.00025 -0.003493 -0.003368 0.017137 0.002731</velocity>
          <acceleration>0.57849 0.143777 -6.85621 -2.41163 0.871111 -3.0992</acceleration>
          <wrench>3.28004 0.815215 -38.8747 0 -0 0</wrench>
        </link>
        <link name='left_wheel'>
          <pose frame=''>0.289684 0.168101 0.109996 1.57083 0.279265 -2.94476</pose>
          <velocity>0.002129 0.000208 -0.00522 -0.007203 0.028323 0.002778</velocity>
          <acceleration>-1.11387 -0.277248 -10.2284 -2.85123 -0.569014 0.236367</acceleration>
          <wrench>-1.67081 -0.415872 -15.3426 0 -0 0</wrench>
        </link>
        <link name='right_wheel'>
          <pose frame=''>0.356212 -0.165327 0.109997 1.57089 -0.345575 -2.94474</pose>
          <velocity>0.003053 0.000394 -0.005248 -0.00882 0.036327 0.002717</velocity>
          <acceleration>-1.07282 -0.266229 -10.3204 -2.88981 -0.575988 0.02205</acceleration>
          <wrench>-1.60923 -0.399343 -15.4807 0 -0 0</wrench>
        </link>
      </model>
      
      <light name='sun'>
        <pose frame=''>0 0 10 0 -0 0</pose>
      </light>
    </state>
    <gui fullscreen='0'>
      <camera name='user_camera'>
        <pose frame=''>6.71178 -3.73581 2.46333 0 0.347642 2.55619</pose>
        <view_controller>orbit</view_controller>
        <projection_type>perspective</projection_type>
      </camera>
    </gui>
  </world>
</sdf>
